Workbook

Sheet OBSERVACIÓN
A1: OBSERVACIÓN SOT
A2: Rechazada | B2: FECHA | C2: NÚMERO | D2: FACTUR. | F2: 150 MB CLARO TV AVANZADO | G2: 125
A3: Reasignación | B3: 45474 | C3: 45474 | D3: 45476 | F3: 150 MB CLARO TV AVANZADO 1000 | G3: 126
A4: En ejecución | B4: 45475 | C4: 45475 | D4: 45476 | F4: 150 MB HD TV AVANZADO | G4: 125
A5: Atendida | B5: 45476 | C5: 45476 | D5: 45477 | F5: 150 MB TELEFONIA 1000 | G5: 66
B6: 45477 | C6: 45477 | D6: 45478 | F6: 150 MB TELEFONIA 5000 | G6: 70
B7: 45478 | C7: 45478 | D7: 45479 | F7: 150 MB TV AVANZADO PRO | G7: 150
B8: 45479 | C8: 45479 | D8: 45481 | F8: 150 MB TV AVANZADO PRO 5000 | G8: 155
B9: 45480 | C9: 45480 | D9: 45481 | F9: 300 MB CLARO TV AVANZADO | G9: 135
B10: 45481 | C10: 45481 | D10: 45482 | F10: 300 MB HD TV AVANZADO 1000 | G10: 136
B11: 45482 | C11: 45482 | D11: 45484 | F11: 300 MB TELEFONIA 1000 | G11: 76
A12: OBSERVACIÓN AUDIO | B12: 45483 | C12: 45483 | D12: 45484 | F12: 300 MB TV AVANZADO PRO | G12: 160
A13: Conforme | B13: 45484 | C13: 45484 | D13: 45485 | F13: 400 MB HD TV AVANZADO | G13: 145
A14: Observado | B14: 45485 | C14: 45485 | D14: 45487 | F14: 400 MB TELEFONIA 1000 | G14: 86
B15: 45486 | C15: 45486 | D15: 45487 | F15: 400 MB TV AVANZADO PRO | G15: 170
B16: 45487 | C16: 45487 | D16: 45489 | F16: FTTH EMP DIG 150MB | G16: 65
B17: 45488 | C17: 45488 | D17: 45489 | F17: FTTH EMP DIG 150MB TELEFONIA 1000 | G17: 66
B18: 45489 | C18: 45489 | D18: 45491 | F18: FTTH EMP DIG 150MB TV AVANZADO | G18: 125
A19: PAGOS | B19: 45490 | C19: 45490 | D19: 45491 | F19: FTTH EMP DIG 150MB TV AVANZADO PRO | G19: 150
A20: ü | B20: 45491 | C20: 45491 | D20: 45492 | F20: FTTH EMP DIG 300MB | G20: 75
B21: 45492 | C21: 45492 | D21: 45493 | F21: FTTH EMP DIG 300MB TV AVANZADO | G21: 135
B22: 45493 | C22: 45493 | D22: 45495 | F22: FTTH EMP DIG 300MB TV AVANZADO PRO | G22: 160
B23: 45494 | C23: 45494 | D23: 45495 | F23: HFC EMP DIG 150MB | G23: 65
A24: M | B24: 45495 | C24: 45495 | D24: 45497 | F24: HFC EMP DIG 150MB HDTV AVANZADO | G24: 125
A25: F | B25: 45496 | C25: 45496 | D25: 45497 | F25: HFC EMP DIG 150MB TELEFONIA 1000 | G25: 66
B26: 45497 | C26: 45497 | D26: 45498 | F26: HFC EMP DIG 300MB | G26: 75
A27: CORPORATIVO | B27: 45498 | C27: 45498 | D27: 45499 | F27: INTERNET 1000MB | G27: 145
A28: MASIVO | B28: 45499 | C28: 45499 | D28: 45501 | F28: INTERNET 150MB | G28: 65
B29: 45500 | C29: 45500 | D29: 45501 | F29: INTERNET 300MB | G29: 75
B30: 45501 | C30: 45501 | D30: 45505 | F30: INTERNET 400MB | G30: 85
A31: CALL | B31: 45502 | C31: 45502 | D31: 45505 | F31: HFC EMP DIG 150MB TELEFONIA 5000 | G31: 70
A32: CAMPO | B32: 45503 | C32: 45503 | D32: 45505 | F32: 300 MB TELEFONIA 5000 | G32: 80
B33: 45504 | C33: 45504 | D33: 45505 | F33: FTTH EMP DIG 300MB TV AVANZADO PRO | G33: 160
B34: 45505 | C34: 45505 | D34: 45507 | F34: 300 MB TV AVANZADO PRO 5000 | G34: 165
B35: 45506 | C35: 45506 | D35: 45507 | F35: 300 MB TELEFONIA 5000 | G35: 80
B36: 45507 | C36: 45507 | D36: 45508 | F36: FTTH EMP DIG 150MB TELEFONIA 5000 | G36: 70
B37: 45508 | C37: 45508 | D37: 45509 | F37: HFC EMP DIG 300MB TV AVANZADO PRO | G37: 160
B38: 45509 | C38: 45509 | D38: 45510 | F38: 400 MB TV AVANZADO PRO | G38: 170
B39: 45510 | C39: 45510 | D39: 45512 | F39: FTTH EMP DIG 300MB TV AVANZADO PRO 5000 | G39: 165
B40: 45511 | C40: 45511 | D40: 45512 | F40: 150 MB TV ESTANDAR PRO | G40: 150
...

Sheet BASE DE VENTAS
A1: ITEM | B1: DNI/RUC | C1: CLIENTE | D1: SEC | E1: SOT | F1: TIPO | G1: TECN. | H1: PLAN | I1: C.FIJO | J1: SCORE | K1: COMEN | L1: EST.SOT | M1: FECHAINST. | N1: EST.AUDIO | O1: AUDIO | P1: SUBIDA | Q1: SUPERV | R1: ASESOR | S1: FECHAVENTA | T1: MES | U1: MES INST. | V1: CELULAR | W1: C.PAGO | X1: AÑO | Y1: AÑO INST. | Z1: DEPARTAMENTO | AA1: GÉNERO | AB1: MODALIDAD
A2: 1 | B2: 16654035 | C2: GLADYS VILLALOBOS AYALA | D2: 85276789 | E2: 72113719 | F2: MASIVO | G2: FTTH | H2: INTERNET 150MB | I2: =IFERROR(VLOOKUP(H2,OBSERVACIÓN!F$2:G$151,2,0),"") -> 65 | K2: - | L2: Atendida | M2: 45487 | N2: Conforme | O2: ü | P2: 45500 | Q2: SUPERV1 | R2: BAJAS | S2: 45485 | T2: =IF(ISNUMBER(S2)=TRUE, MONTH(S2), " ") -> 7 | U2: =IF(ISNUMBER(M2)=TRUE, MONTH(M2), " ") -> 7 | V2: 942078232 | W2: H54092674 | X2: =IF(ISNUMBER(S2)=TRUE, YEAR(S2), " ") -> 2024 | Y2: =IF(ISNUMBER(M2)=TRUE, YEAR(M2), " ") -> 2024 | Z2: LAMBAYEQUE | AA2: F | AB2: CALL
A3: =A2+1 -> 2 | B3: 76047253 | C3: MARIA BETH LEON ROSALES | D3: 85397069 | E3: 72162975 | F3: MASIVO | G3: FTTH | H3: INTERNET 150MB | I3: =IFERROR(VLOOKUP(H3,OBSERVACIÓN!F$2:G$151,2,0),"") -> 65 | K3: - | L3: Atendida | M3: 45490 | N3: Conforme | O3: ü | P3: 45498 | Q3: SUPERV1 | R3: BAJAS | S3: 45489 | T3: =IF(ISNUMBER(S3)=TRUE, MONTH(S3), " ") -> 7 | U3: =IF(ISNUMBER(M3)=TRUE, MONTH(M3), " ") -> 7 | V3: 998043005 | W3: H54102710 | X3: =IF(ISNUMBER(S3)=TRUE, YEAR(S3), " ") -> 2024 | Y3: =IF(ISNUMBER(M3)=TRUE, YEAR(M3), " ") -> 2024 | Z3: ANCASH | AA3: F | AB3: CALL
A4: =A3+1 -> 3 | B4: 75126726 | C4: JOSEPH DANIEL RUIZ MADERO | D4: 85476765 | E4: 72203884 | F4: MASIVO | G4: FTTH | H4: 300 MB CLARO TV AVANZADO | I4: =IFERROR(VLOOKUP(H4,OBSERVACIÓN!F$2:G$151,2,0),"") -> 135 | K4: - | L4: Atendida | M4: 45495 | N4: Conforme | O4: ü | P4: 45531 | Q4: SUPERV1 | R4: BAJAS | S4: 45491 | T4: =IF(ISNUMBER(S4)=TRUE, MONTH(S4), " ") -> 7 | U4: =IF(ISNUMBER(M4)=TRUE, MONTH(M4), " ") -> 7 | V4: 991005090 | W4: H54114535 | X4: =IF(ISNUMBER(S4)=TRUE, YEAR(S4), " ") -> 2024 | Y4: =IF(ISNUMBER(M4)=TRUE, YEAR(M4), " ") -> 2024 | Z4: LAMBAYEQUE | AA4: F | AB4: CALL
A5: =A4+1 -> 4 | B5: 16754525 | C5: YENI MAGALI SIGUEÑAS BARBOZA | D5: 85469463 | E5: 72200816 | F5: MASIVO | G5: FTTH | H5: INTERNET 150MB | I5: =IFERROR(VLOOKUP(H5,OBSERVACIÓN!F$2:G$151,2,0),"") -> 65 | K5: - | L5: Atendida | M5: 45494 | N5: Conforme | O5: ü | Q5: SUPERV1 | R5: BAJAS | S5: 45492 | T5: =IF(ISNUMBER(S5)=TRUE, MONTH(S5), " ") -> 7 | U5: =IF(ISNUMBER(M5)=TRUE, MONTH(M5), " ") -> 7 | V5: 969916302 | W5: H54122149 | X5: =IF(ISNUMBER(S5)=TRUE, YEAR(S5), " ") -> 2024 | Y5: =IF(ISNUMBER(M5)=TRUE, YEAR(M5), " ") -> 2024 | Z5: LAMBAYEQUE | AA5: F | AB5: CALL
A6: =A5+1 -> 5 | B6: 72558453 | C6: CARLA GERALDIN MIO FASABI | D6: 85514423 | E6: 72222769 | F6: MASIVO | G6: HFC | H6: INTERNET 150MB | I6: =IFERROR(VLOOKUP(H6,OBSERVACIÓN!F$2:G$151,2,0),"") -> 65 | K6: - | L6: Atendida | M6: 45500 | N6: Conforme | O6: ü | P6: 45528 | Q6: SUPERV1 | R6: BAJAS | S6: 45493 | T6: =IF(ISNUMBER(S6)=TRUE, MONTH(S6), " ") -> 7 | U6: =IF(ISNUMBER(M6)=TRUE, MONTH(M6), " ") -> 7 | V6: 923495184 | W6: H54123687 | X6: =IF(ISNUMBER(S6)=TRUE, YEAR(S6), " ") -> 2024 | Y6: =IF(ISNUMBER(M6)=TRUE, YEAR(M6), " ") -> 2024 | Z6: LAMBAYEQUE | AA6: F | AB6: CALL
A7: =A6+1 -> 6 | B7: 70689403 | C7: DIANA CLAUDIA ZULOETA MENDOZA | D7: 85524326 | E7: 72227659 | F7: MASIVO | G7: FTTH | H7: INTERNET 150MB | I7: =IFERROR(VLOOKUP(H7,OBSERVACIÓN!F$2:G$151,2,0),"") -> 65 | K7: - | L7: Atendida | M7: 45500 | N7: Conforme | O7: ü | P7: 45530 | Q7: SUPERV1 | R7: BAJAS | S7: 45496 | T7: =IF(ISNUMBER(S7)=TRUE, MONTH(S7), " ") -> 7 | U7: =IF(ISNUMBER(M7)=TRUE, MONTH(M7), " ") -> 7 | V7: 988714135 | W7: H54136323 | X7: =IF(ISNUMBER(S7)=TRUE, YEAR(S7), " ") -> 2024 | Y7: =IF(ISNUMBER(M7)=TRUE, YEAR(M7), " ") -> 2024 | Z7: LAMBAYEQUE | AA7: M | AB7: CALL
A8: =A7+1 -> 7 | B8: 60986479 | C8: MARLON ISAAC LEYVA SILVA | D8: 85623883 | E8: 72255519 | F8: MASIVO | G8: FTTH | H8: INTERNET 150MB | I8: =IFERROR(VLOOKUP(H8,OBSERVACIÓN!F$2:G$151,2,0),"") -> 65 | K8: - | L8: Atendida | M8: 45498 | N8: Conforme | O8: ü | P8: 45507 | Q8: SUPERV1 | R8: BAJAS | S8: 45497 | T8: =IF(ISNUMBER(S8)=TRUE, MONTH(S8), " ") -> 7 | U8: =IF(ISNUMBER(M8)=TRUE, MONTH(M8), " ") -> 7 | V8: 997016943 | W8: H54144298 | X8: =IF(ISNUMBER(S8)=TRUE, YEAR(S8), " ") -> 2024 | Y8: =IF(ISNUMBER(M8)=TRUE, YEAR(M8), " ") -> 2024 | Z8: LAMBAYEQUE | AA8: M | AB8: CALL
A9: =A8+1 -> 8 | B9: 71500252 | C9: NICOLLE DEL ROSARIO CHIMOY MIO | D9: 85613761 | E9: 72253617 | F9: MASIVO | G9: FTTH | H9: INTERNET 150MB | I9: =IFERROR(VLOOKUP(H9,OBSERVACIÓN!F$2:G$151,2,0),"") -> 65 | K9: - | L9: Atendida | M9: 45498 | N9: Conforme | O9: ü | P9: 45505 | Q9: SUPERV1 | R9: BAJAS | S9: 45497 | T9: =IF(ISNUMBER(S9)=TRUE, MONTH(S9), " ") -> 7 | U9: =IF(ISNUMBER(M9)=TRUE, MONTH(M9), " ") -> 7 | V9: 979212381 | W9: H54139718 | X9: =IF(ISNUMBER(S9)=TRUE, YEAR(S9), " ") -> 2024 | Y9: =IF(ISNUMBER(M9)=TRUE, YEAR(M9), " ") -> 2024 | Z9: LAMBAYEQUE | AA9: M | AB9: CALL
A10: =A9+1 -> 9 | B10: 71054020 | C10: HUGO QUIÑONES MENDOZA | D10: 85608847 | E10: 72252719 | F10: MASIVO | G10: FTTH | H10: INTERNET 150MB | I10: =IFERROR(VLOOKUP(H10,OBSERVACIÓN!F$2:G$151,2,0),"") -> 65 | K10: - | L10: Atendida | M10: 45487 | N10: Conforme | O10: ü | P10: 45498 | Q10: SUPERV1 | R10: BAJAS | S10: 45500 | T10: =IF(ISNUMBER(S10)=TRUE, MONTH(S10), " ") -> 7 | U10: =IF(ISNUMBER(M10)=TRUE, MONTH(M10), " ") -> 7 | V10: 993853319 | W10: H54085634 | X10: =IF(ISNUMBER(S10)=TRUE, YEAR(S10), " ") -> 2024 | Y10: =IF(ISNUMBER(M10)=TRUE, YEAR(M10), " ") -> 2024 | Z10: LAMBAYEQUE | AA10: M | AB10: CALL
A11: =A10+1 -> 10 | B11: 80216626 | C11: EDWIN ALEJANDRO AURAZO HERNANDEZ | D11: 85657311 | E11: 72300889 | F11: MASIVO | G11: FTTH | H11: INTERNET 150MB | I11: =IFERROR(VLOOKUP(H11,OBSERVACIÓN!F$2:G$151,2,0),"") -> 65 | K11: - | L11: Atendida | M11: 45502 | N11: Conforme | O11: ü | P11: 45507 | Q11: SUPERV1 | R11: BAJAS | S11: 45500 | T11: =IF(ISNUMBER(S11)=TRUE, MONTH(S11), " ") -> 7 | U11: =IF(ISNUMBER(M11)=TRUE, MONTH(M11), " ") -> 7 | V11: 956612862 | W11: H54158898 | X11: =IF(ISNUMBER(S11)=TRUE, YEAR(S11), " ") -> 2024 | Y11: =IF(ISNUMBER(M11)=TRUE, YEAR(M11), " ") -> 2024 | Z11: LAMBAYEQUE | AA11: F | AB11: CALL

Sheet EJECUCION
B1: CLIENTE | C1: SOT | D1: DIA DE INSTALACION | E1: ASESOR | F1: FECHAVENTA | G1: DEPARTAMENTO | H1: MODALIDAD
A2: 44885022 | B2: NATALY PEREZ PAUCAR | C2: 84181823 | D2: 18/01/2026 AM1 | E2: Merlyn Bravo | F2: 46037 | G2: JUNIN | H2: CALL
A3: 25779443 | B3: MARIA DEL CARMEN MOGOLLON CHUMPITAZ | C3: 84288793 | D3: 21/01/2026 AM1 | E3: Hector Ordoñez | F3: 46042 | G3: CALLAO | H3: CALL
A4: 32121118 | B4: ANA MARIA MORENO ALEGRE | C4: 84296978 | D4: 24/01/2026 AM2 | E4: Jose Sanchez | F4: 46042 | G4: ANCASH | H4: CALL
A5: 22477027 | B5: BARDONIO LIVIA CORNE | C5: 84314000 | D5: 23/01/2026 PM2 | E5: Evelyn Effio | F5: 46043 | G5: LAMBAYEQUE | H5: CALL
A6: 77674451 | B6: ALONZO ROLANDO HUARCAYA NEYRA | C6: 84315966 | D6: 25/01/2026 PM2 | E6: Irving Cordova | F6: 46043 | G6: ICA | H6: CALL
A7: 81010256 | B7: YAMILA MARTHA ROJAS VALVERDE | C7: 84335673 | D7: 23/01/2026 AM2 | E7: Evelyn Effio | F7: 46044 | G7: LIMA | H7: CALL
A8: 44609204 | B8: LENNY PAOLA CHU PEZO | C8: 84335956 | D8: 29/01/2026 PM1 | E8: Nadia Muncibay | F8: 46044 | G8: SAN MARTIN | H8: CALL
A9: 72074469 | B9: BOCANGEL BELTRAN LESLY SERGIÑA | C9: 84336608 | D9: 22/01/2026 PM1 | E9: Jerson Becerra | F9: 46044 | G9: LIMA | H9: CALL
A10: 20559212700 | B10: GRUPO COINGCO S.A.C. | C10: 84101193 | D10: 25/01/2026 PM1 | E10: Evelyn Effio | F10: 46044 | G10: AREQUIPA | H10: CALL
A11: 41410739 | B11: MASHA ARAUJO LAGONES | C11: 84340833 | D11: 25/01/2026 PM1 | E11: Merlyn Bravo | F11: 46044 | G11: JUNIN | H11: CALL
A12: 17824052 | B12: JUAN OSWALDO ZAVALETA REYES | C12: 84345948 | D12: 25/01/2026 AM1 | E12: Luz Guevara | F12: 46044 | G12: LA LIBERTAD | H12: CALL
A13: 10004047503 | B13: QUIÑONES VALERIANA RUFINO | C13: 84366062 | D13: 24/01/2026 AM2 | E13: Irving Cordova | F13: 46045 | G13: TACNA | H13: CALL
... A23: 9518142 | B23: WILSON AGAPITO CHUQUIMUNI LUYO | C23: 84387851 | D23: 27/01/2026 AM1 | E23: Jeaneth Ventura | F23: 46046 | G23: LIMA | H23: CALL

Sheet VENTAS PERDIDAS
A1: ITEM | B1: DNI | C1: CLIENTE | D1: SEC | E1: SOT | F1: TEC. | G1: PLAN | H1: C.FIJO | I1: SCORE | J1: COMENT. | K1: ESTADO SOT | L1: FECH INST | M1: ESTADO AUDIO | N1: AUDIO | O1: SUBIDA | P1: SUPERVISOR | Q1: ASESOR | R1: FCH VENTA | S1: MES
A2: 1 | B2: 18106340 | C2: MARIA ALEJANDRINA PAZ ABANTO | D2: 85395370 | E2: 72162545 | J2: - | K2: Rechazada | P2: Lenin Chaname | Q2: Jennifer López | R2: 45489 | S2: =IF(ISNUMBER(R2)=TRUE, MONTH(R2), " ") -> 7
A3: =A2+1 -> 2 | B3: 2777326 | C3: BERTHA CHAVEZ SULLON | D3: 85461214 | E3: 72197811 | J3: - | K3: Rechazada | O3: 45491 | P3: Lenin Chaname | Q3: Flavia Zuloeta | R3: 45491 | S3: =IF(ISNUMBER(R3)=TRUE, MONTH(R3), " ") -> 7
A4: =A3+1 -> 3 | B4: 18024289 | C4: VICTOR ROMAN ESCOBAR LARRIVIERE | D4: 85427027 | E4: 72204545 | J4: - | K4: Rechazada | P4: Lenin Chaname | Q4: Yoselin Guevara | R4: 45491 | S4: =IF(ISNUMBER(R4)=TRUE, MONTH(R4), " ") -> 7
A5: =A4+1 -> 4 | B5: 72360534 | C5: KELLY IRINA CABRERA SANCHEZ | D5: 85657798 | E5: 72301284 | J5: - | K5: Rechazada | L5: 45500 | P5: Lenin Chaname | Q5: Yoselin Guevara | R5: 45497 | S5: =IF(ISNUMBER(R5)=TRUE, MONTH(R5), " ") -> 7
A6: =A5+1 -> 5 | B6: 76591146 | C6: JHEIMY DEL MILAGRO ROJAS GASTELO | D6: 85630585 | E6: 72280472 | J6: - | K6: Rechazada | L6: 45497 | P6: Lenin Chaname | Q6: Yoselin Guevara | R6: 45497 | S6: =IF(ISNUMBER(R6)=TRUE, MONTH(R6), " ") -> 7
A7: =A6+1 -> 6 | B7: 72594263 | C7: CAMILA YAMILEHT MENDOZA DELGADO | D7: 72319278 | E7: 72319278 | J7: - | K7: Rechazada | L7: 45501 | P7: Lenin Chaname | Q7: Andy Aurazo | R7: 45498 | S7: =IF(ISNUMBER(R7)=TRUE, MONTH(R7), " ") -> 7
A8: =A7+1 -> 7 | B8: 71577918 | C8: EXON AYMAR CRUZ ROMERO | D8: 85695905 | E8: 72335926 | J8: - | K8: Rechazada | L8: 45518 | P8: Lenin Chaname | Q8: Carla Mío | R8: 45499 | S8: =IF(ISNUMBER(R8)=TRUE, MONTH(R8), " ") -> 7
A9: =A8+1 -> 8 | B9: 76038577 | C9: CRISTOFERH PAUL SILVA ENRRIQUEZ | D9: 85728912 | E9: 72346961 | J9: - | K9: Rechazada | L9: 45507 | O9: 45500 | P9: Lenin Chaname | Q9: Yoselin Guevara | R9: 45500 | S9: =IF(ISNUMBER(R9)=TRUE, MONTH(R9), " ") -> 7
A10: =A9+1 -> 9 | B10: 75185359 | C10: JAKELINE STEFANY GALAN FIESTAS | D10: 85752986 | E10: 72352113 | J10: - | K10: Rechazada | L10: 45504 | O10: 45491 | P10: Lenin Chaname | Q10: Yoselin Guevara | R10: 45500 | S10: =IF(ISNUMBER(R10)=TRUE, MONTH(R10), " ") -> 7
A11: =A10+1 -> 10 | B11: 42609331 | C11: ROSA VICTORIA BALLENA GAMARRA | D11: 85753094 | E11: 72352153 | J11: - | K11: Rechazada | L11: 45506 | P11: Lenin Chaname | Q11: Yadira Vega | R11: 45500 | S11: =IF(ISNUMBER(R11)=TRUE, MONTH(R11), " ") -> 7
A12: =A11+1 -> 11 | B12: 75319248 | C12: ANDY JHAMIL AURAZO CARHUATANTA | D12: 85753237 | E12: 72352210 | J12: - | K12: Rechazada | L12: 45514 | P12: Lenin Chaname | Q12: Flavia Zuloeta | R12: 45500 | S12: =IF(ISNUMBER(R12)=TRUE, MONTH(R12), " ") -> 7
A13: =A12+1 -> 12 | B13: 77387732 | C13: ANGIE LUZ MENDOZA GUERRERO | D13: 85743426 | E13: 72349980 | J13: - | K13: Rechazada | L13: 45504 | P13: Lenin Chaname | Q13: Yoselin Guevara | R13: 45505 | S13: =IF(ISNUMBER(R13)=TRUE, MONTH(R13), " ") -> 8
A14: =A13+1 -> 13 | B14: 16452757 | C14: SEGUNDO MANUEL SALAZAR VERA | D14: 86014773 | E14: 72525363 | J14: - | K14: Rechazada | L14: 45538 | P14: Lenin Chaname | Q14: Yoselin Guevara | R14: 45506 | S14: =IF(ISNUMBER(R14)=TRUE, MONTH(R14), " ") -> 8
A15: =A14+1 -> 14 | B15: 32973347 | C15: JORGE LUIS NORIEGA VARGAS | D15: 86070850 | E15: 72602884 | J15: - | K15: Rechazada | P15: Lenin Chaname | Q15: Cynthia Puican | R15: 45512 | S15: =IF(ISNUMBER('BASE DE VENTAS'!#REF!)=TRUE, MONTH('BASE DE VENTAS'!#REF!), " ")
A16: =A15+1 -> 15 | B16: 72667624 | C16: JULIO CESAR LOZADA VEINTIMILLA | D16: 86197717 | E16: 72664479 | J16: - | K16: Rechazada | L16: 45517 | P16: Lenin Chaname | Q16: Carla Mío | R16: 45513 | S16: =IF(ISNUMBER(R16)=TRUE, MONTH(R16), " ") -> 8
A17: =A16+1 -> 16 | B17: 10436871801 | C17: CHANCAFE ÑIQUEN CESAR AUGUSTO | D17: 86161921 | E17: 72639632 | J17: - | K17: Rechazada | P17: Lenin Chaname | Q17: Yoselin Guevara | R17: 45513 | S17: =IF(ISNUMBER(R17)=TRUE, MONTH(R17), " ") -> 8
A18: =A17+1 -> 17 | B18: 247118 | C18: JORGE ENRIQUE ZAPATA DIOS | D18: 86101360 | E18: 72601683 | J18: - | K18: Rechazada | P18: Lenin Chaname | Q18: Andy Aurazo | R18: 45513 | S18: =IF(ISNUMBER(R18)=TRUE, MONTH(R18), " ") -> 8
A19: =A18+1 -> 18 | B19: 72793661 | C19: JEREMY YADIRA VEGA VASQUEZ | D19: 86124145 | E19: 72610949 | J19: - | K19: Rechazada | L19: 45523 | P19: Lenin Chaname | Q19: Andy Aurazo | R19: 45514 | S19: =IF(ISNUMBER(R19)=TRUE, MONTH(R19), " ") -> 8
A20: =A19+1 -> 19 | B20: 32957202 | C20: MARIA NIEVES SANCHEZ MEJIA | D20: 86130017 | E20: 72612141 | J20: - | K20: Rechazada | L20: 45515 | P20: Lenin Chaname | Q20: Yoselin Guevara | R20: 45514 | S20: =IF(ISNUMBER(R20)=TRUE, MONTH(R20), " ") -> 8
A21: =A20+1 -> 20 | B21: 72793661 | C21: JEREMY YADIRA VEGA VASQUEZ | D21: 85790512 | E21: 72381570 | J21: - | K21: Rechazada | L21: 45514 | P21: Lenin Chaname | Q21: Yadira Vega | R21: 45514 | S21: =IF(ISNUMBER(R21)=TRUE, MONTH(R21), " ") -> 8
A22: =A21+1 -> 21 | B22: 16591518 | C22: SUSANA ISMELDA GORDILLO PESCORAN | D22: 86126971 | E22: 72611484 | J22: - | K22: Rechazada | P22: Lenin Chaname | Q22: Cynthia Puican | R22: 45514 | S22: =IF(ISNUMBER(R22)=TRUE, MONTH(R22), " ") -> 8
A23: =A22+1 -> 22 | B23: 79052449 | C23: GUILLERMINA ANGELICA VILLALOBOS CASTILLO | D23: 86127823 | E23: 72611713 | J23: - | K23: Rechazada | P23: Lenin Chaname | Q23: Nicolle Chimoy | R23: 45514 | S23: =IF(ISNUMBER(R23)=TRUE, MONTH(R23), " ") -> 8
A24: =A23+1 -> 23 | B24: 16540323 | C24: ROSA YSABEL CHAMORRO ASCENCIO | D24: 86132435 | E24: 72612627 | J24: - | K24: Rechazada | P24: Lenin Chaname | Q24: Carla Mío | R24: 45514 | S24: =IF(ISNUMBER(R24)=TRUE, MONTH(R24), " ") -> 8
A25: =A24+1 -> 24 | B25: 10727936608 | C25: ANGIE LISETH VEGA VASQUEZ | D25: 86339316 | E25: 72750250 | J25: - | K25: Rechazada | P25: Lenin Chaname | Q25: Yadira Vega | R25: 45514 | S25: =IF(ISNUMBER(R25)=TRUE, MONTH(R25), " ") -> 8
A26: =A25+1 -> 25 | B26: 2694046 | C26: LUIS ALBERTO RISCO FERNANDEZ | D26: 86194074 | E26: 72652780 | J26: - | K26: Rechazada | L26: 45518 | P26: Lenin Chaname | Q26: Nicolle Chimoy | R26: 45516 | S26: =IF(ISNUMBER(R26)=TRUE, MONTH(R26), " ") -> 8
A27: =A26+1 -> 26 | B27: 76645091 | C27: CESAR JESUS BRIONES MILLONES | D27: 86199062 | E27: 72664864 | J27: - | K27: Rechazada | P27: Lenin Chaname | Q27: Andy Aurazo | R27: 45517 | S27: =IF(ISNUMBER(R27)=TRUE, MONTH(R27), " ") -> 8
A28: =A27+1 -> 27 | B28: 42348288 | C28: KELY YOHANA ZAMORA MEZA | D28: 86212166 | E28: 72699812 | J28: - | K28: Rechazada | P28: Lenin Chaname | Q28: Cynthia Puican | R28: 45517 | S28: =IF(ISNUMBER(R28)=TRUE, MONTH(R28), " ") -> 8
A29: =A28+1 -> 28 | B29: 16655405 | C29: MARIA GREGORIA MINO CARDENAS | D29: 86246961 | E29: 72698369 | J29: - | K29: Rechazada | P29: Lenin Chaname | Q29: Yoselin Guevara | R29: 45518 | S29: =IF(ISNUMBER(R29)=TRUE, MONTH(R29), " ") -> 8
A30: =A29+1 -> 29 | B30: 48674723 | C30: JHAIR EMANUEL LLONTOP RELUZ | D30: 86263698 | E30: 72711804 | J30: - | K30: Rechazada | L30: 45527 | P30: Lenin Chaname | Q30: Yoselin Guevara | R30: 45519 | S30: =IF(ISNUMBER(R30)=TRUE, MONTH(R30), " ") -> 8
A31: =A30+1 -> 30 | B31: 73468060 | C31: NATHALY DEL PILAR PEREZ ODAR | D31: 86320047 | E31: 72740833 | J31: - | K31: Rechazada | P31: Lenin Chaname | Q31: Andy Aurazo | R31: 45520 | S31: =IF(ISNUMBER(R31)=TRUE, MONTH(R31), " ") -> 8
A32: =A31+1 -> 31 | B32: 10628088 | C32: GIULIANA SILVIA GARCIA CORDOVA | D32: 86352945 | E32: 72775208 | J32: - | K32: Rechazada | P32: Lenin Chaname | Q32: Nicolle Chimoy | R32: 45521 | S32: =IF(ISNUMBER(R32)=TRUE, MONTH(R32), " ") -> 8
A33: =A32+1 -> 32 | B33: 42917972 | C33: RAUL SEGUNDO HERNANDEZ VASQUEZ | D33: 86437130 | E33: 72799560 | J33: - | K33: Rechazada | P33: Lenin Chaname | Q33: Nicolle Chimoy | R33: 45524 | S33: =IF(ISNUMBER(R33)=TRUE, MONTH(R33), " ") -> 8
A34: =A33+1 -> 33 | B34: 47798797 | C34: DEICY MARIBEL PORTALATINO MELENDEZ | D34: 86496976 | E34: 72902763 | J34: - | K34: Rechazada | P34: Lenin Chaname | Q34: Carla Mío | R34: 45526 | S34: =IF(ISNUMBER(R34)=TRUE, MONTH(R34), " ") -> 8
A35: =A34+1 -> 34 | B35: 20610823140 | C35: CALZADOS RB MODA BRASIL E.I.R.L. | D35: 86556759 | E35: 72916989 | J35: - | K35: Rechazada | P35: Lenin Chaname | Q35: Blanca Chapoñan | R35: 45528 | S35: =IF(ISNUMBER(R35)=TRUE, MONTH(R35), " ") -> 8
A36: =A35+1 -> 35 | B36: 42364277 | C36: ENRIQUE MALDONADO MENDOZA | D36: 86620179 | E36: 72951944 | J36: - | K36: Rechazada | L36: 45533 | P36: Lenin Chaname | Q36: Nicolle Chimoy | R36: 45530 | S36: =IF(ISNUMBER(R36)=TRUE, MONTH(R36), " ") -> 8
A37: =A36+1 -> 36 | B37: 46534586 | C37: DEIVIS DANIEL MANAYAY GALLO | D37: 86652573 | E37: 72979174 | J37: - | K37: Rechazada | P37: Lenin Chaname | Q37: Yoselin Guevara | R37: 45531 | S37: =IF(ISNUMBER(R37)=TRUE, MONTH(R37), " ") -> 8
A38: =A37+1 -> 37 | B38: 20602225021 | C38: GRUPO ATLAY PERU SAC | D38: 86636312 | E38: 72972995 | J38: - | K38: Rechazada | L38: 45533 | P38: Lenin Chaname | Q38: Cynthia Puican | R38: 45531 | S38: =IF(ISNUMBER(R38)=TRUE, MONTH(R38), " ") -> 8
A39: =A38+1 -> 38 | B39: 48019444 | C39: EDUARDO ROBERTO REYES ALARCON | D39: 86646564 | E39: 72976710 | J39: - | K39: Rechazada | P39: Lenin Chaname | Q39: Blanca Chapoñan | R39: 45531 | S39: =IF(ISNUMBER(R39)=TRUE, MONTH(R39), " ") -> 8
A40: =A39+1 -> 39 | B40: 16708381 | C40: PASCUALA MAS PUERTA VDA DE SOTERO | D40: 86682552 | E40: 73002342 | J40: - | K40: Rechazada | L40: 45533 | P40: Lenin Chaname | Q40: Ethel Quispe | R40: 45532 | S40: =IF(ISNUMBER(R40)=TRUE, MONTH(R40), " ") -> 8
...
